[2024-08-19T11:08:51.715+0500] {local_task_job_runner.py:120} INFO - ::group::Pre task execution logs
[2024-08-19T11:08:51.733+0500] {taskinstance.py:2076} INFO - Dependencies all met for dep_context=non-requeueable deps ti=<TaskInstance: 3_models_dag.save_results manual__2024-08-19T06:08:23.428322+00:00 [queued]>
[2024-08-19T11:08:51.741+0500] {taskinstance.py:2076} INFO - Dependencies all met for dep_context=requeueable deps ti=<TaskInstance: 3_models_dag.save_results manual__2024-08-19T06:08:23.428322+00:00 [queued]>
[2024-08-19T11:08:51.741+0500] {taskinstance.py:2306} INFO - Starting attempt 1 of 1
[2024-08-19T11:08:51.753+0500] {taskinstance.py:2330} INFO - Executing <Task(PythonOperator): save_results> on 2024-08-19 06:08:23.428322+00:00
[2024-08-19T11:08:51.765+0500] {standard_task_runner.py:90} INFO - Running: ['airflow', 'tasks', 'run', '3_models_dag', 'save_results', 'manual__2024-08-19T06:08:23.428322+00:00', '--job-id', '325', '--raw', '--subdir', 'DAGS_FOLDER/.ipynb_checkpoints/train_models-2-checkpoint.py', '--cfg-path', '/tmp/tmpc2nkiz2b']
[2024-08-19T11:08:51.767+0500] {standard_task_runner.py:91} INFO - Job 325: Subtask save_results
[2024-08-19T11:08:51.769+0500] {logging_mixin.py:188} WARNING - /home/nicolaspc/anaconda3/envs/mlops_env/lib/python3.12/site-packages/airflow/task/task_runner/standard_task_runner.py:62 DeprecationWarning: This process (pid=6639) is multi-threaded, use of fork() may lead to deadlocks in the child.
[2024-08-19T11:08:51.769+0500] {standard_task_runner.py:64} INFO - Started process 6662 to run task
[2024-08-19T11:08:51.819+0500] {task_command.py:426} INFO - Running <TaskInstance: 3_models_dag.save_results manual__2024-08-19T06:08:23.428322+00:00 [running]> on host nicolaspc-HP-Pavilion-Laptop-15-eh1xxx
[2024-08-19T11:08:51.906+0500] {taskinstance.py:2648} INFO - Exporting env vars: AIRFLOW_CTX_DAG_OWNER='Nicolas Pal' AIRFLOW_CTX_DAG_ID='3_models_dag' AIRFLOW_CTX_TASK_ID='save_results' AIRFLOW_CTX_EXECUTION_DATE='2024-08-19T06:08:23.428322+00:00' AIRFLOW_CTX_TRY_NUMBER='1' AIRFLOW_CTX_DAG_RUN_ID='manual__2024-08-19T06:08:23.428322+00:00'
[2024-08-19T11:08:51.906+0500] {taskinstance.py:430} INFO - ::endgroup::
[2024-08-19T11:08:51.925+0500] {taskinstance.py:441} INFO - ::group::Post task execution logs
[2024-08-19T11:08:51.926+0500] {taskinstance.py:2905} ERROR - Task failed with exception
Traceback (most recent call last):
  File "/home/nicolaspc/anaconda3/envs/mlops_env/lib/python3.12/site-packages/airflow/models/taskinstance.py", line 465, in _execute_task
    result = _execute_callable(context=context, **execute_callable_kwargs)
             ^^^^^^^^^^^^^^^^^^^^^^^^^^^^^^^^^^^^^^^^^^^^^^^^^^^^^^^^^^^^^
  File "/home/nicolaspc/anaconda3/envs/mlops_env/lib/python3.12/site-packages/airflow/models/taskinstance.py", line 432, in _execute_callable
    return execute_callable(context=context, **execute_callable_kwargs)
           ^^^^^^^^^^^^^^^^^^^^^^^^^^^^^^^^^^^^^^^^^^^^^^^^^^^^^^^^^^^^
  File "/home/nicolaspc/anaconda3/envs/mlops_env/lib/python3.12/site-packages/airflow/models/baseoperator.py", line 401, in wrapper
    return func(self, *args, **kwargs)
           ^^^^^^^^^^^^^^^^^^^^^^^^^^^
  File "/home/nicolaspc/anaconda3/envs/mlops_env/lib/python3.12/site-packages/airflow/operators/python.py", line 235, in execute
    return_value = self.execute_callable()
                   ^^^^^^^^^^^^^^^^^^^^^^^
  File "/home/nicolaspc/anaconda3/envs/mlops_env/lib/python3.12/site-packages/airflow/operators/python.py", line 252, in execute_callable
    return self.python_callable(*self.op_args, **self.op_kwargs)
           ^^^^^^^^^^^^^^^^^^^^^^^^^^^^^^^^^^^^^^^^^^^^^^^^^^^^^
  File "/home/nicolaspc/airflow/dags/.ipynb_checkpoints/train_models-2-checkpoint.py", line 145, in save_results
    result.update(model_metrics)
    ^^^^^^
NameError: name 'result' is not defined
[2024-08-19T11:08:51.933+0500] {taskinstance.py:1206} INFO - Marking task as FAILED. dag_id=3_models_dag, task_id=save_results, run_id=manual__2024-08-19T06:08:23.428322+00:00, execution_date=20240819T060823, start_date=20240819T060851, end_date=20240819T060851
[2024-08-19T11:08:51.944+0500] {standard_task_runner.py:110} ERROR - Failed to execute job 325 for task save_results (name 'result' is not defined; 6662)
[2024-08-19T11:08:51.983+0500] {local_task_job_runner.py:243} INFO - Task exited with return code 1
[2024-08-19T11:08:52.000+0500] {taskinstance.py:3503} INFO - 0 downstream tasks scheduled from follow-on schedule check
[2024-08-19T11:08:52.002+0500] {local_task_job_runner.py:222} INFO - ::endgroup::
