[2024-08-21T18:40:00.564+0500] {local_task_job_runner.py:123} INFO - ::group::Pre task execution logs
[2024-08-21T18:40:00.582+0500] {taskinstance.py:2603} INFO - Dependencies all met for dep_context=non-requeueable deps ti=<TaskInstance: 3_models_dag_home.init scheduled__2024-08-20T01:00:00+00:00 [queued]>
[2024-08-21T18:40:00.590+0500] {taskinstance.py:2603} INFO - Dependencies all met for dep_context=requeueable deps ti=<TaskInstance: 3_models_dag_home.init scheduled__2024-08-20T01:00:00+00:00 [queued]>
[2024-08-21T18:40:00.591+0500] {taskinstance.py:2856} INFO - Starting attempt 1 of 1
[2024-08-21T18:40:00.601+0500] {taskinstance.py:2879} INFO - Executing <Task(PythonOperator): init> on 2024-08-20 01:00:00+00:00
[2024-08-21T18:40:00.614+0500] {logging_mixin.py:190} WARNING - /home/nicolaspc/anaconda3/envs/mlops_env/lib/python3.12/site-packages/***/task/task_runner/standard_task_runner.py:70 DeprecationWarning: This process (pid=246486) is multi-threaded, use of fork() may lead to deadlocks in the child.
[2024-08-21T18:40:00.615+0500] {standard_task_runner.py:72} INFO - Started process 246533 to run task
[2024-08-21T18:40:00.614+0500] {standard_task_runner.py:104} INFO - Running: ['***', 'tasks', 'run', '3_models_dag_home', 'init', 'scheduled__2024-08-20T01:00:00+00:00', '--job-id', '108', '--raw', '--subdir', 'DAGS_FOLDER/.ipynb_checkpoints/homework_stepik-checkpoint.py', '--cfg-path', '/tmp/tmpr9htz_db']
[2024-08-21T18:40:00.616+0500] {standard_task_runner.py:105} INFO - Job 108: Subtask init
[2024-08-21T18:40:00.675+0500] {task_command.py:467} INFO - Running <TaskInstance: 3_models_dag_home.init scheduled__2024-08-20T01:00:00+00:00 [running]> on host nicolaspc-HP-Pavilion-Laptop-15-eh1xxx
[2024-08-21T18:40:00.753+0500] {taskinstance.py:3122} INFO - Exporting env vars: AIRFLOW_CTX_DAG_OWNER='Nicolas Pal' AIRFLOW_CTX_DAG_ID='3_models_dag_home' AIRFLOW_CTX_TASK_ID='init' AIRFLOW_CTX_EXECUTION_DATE='2024-08-20T01:00:00+00:00' AIRFLOW_CTX_TRY_NUMBER='1' AIRFLOW_CTX_DAG_RUN_ID='scheduled__2024-08-20T01:00:00+00:00'
[2024-08-21T18:40:00.754+0500] {taskinstance.py:731} INFO - ::endgroup::
[2024-08-21T18:40:00.763+0500] {taskinstance.py:3301} ERROR - Task failed with exception
Traceback (most recent call last):
  File "/home/nicolaspc/anaconda3/envs/mlops_env/lib/python3.12/site-packages/airflow/models/taskinstance.py", line 767, in _execute_task
    result = _execute_callable(context=context, **execute_callable_kwargs)
             ^^^^^^^^^^^^^^^^^^^^^^^^^^^^^^^^^^^^^^^^^^^^^^^^^^^^^^^^^^^^^
  File "/home/nicolaspc/anaconda3/envs/mlops_env/lib/python3.12/site-packages/airflow/models/taskinstance.py", line 733, in _execute_callable
    return ExecutionCallableRunner(
           ^^^^^^^^^^^^^^^^^^^^^^^^
  File "/home/nicolaspc/anaconda3/envs/mlops_env/lib/python3.12/site-packages/airflow/utils/operator_helpers.py", line 252, in run
    return self.func(*args, **kwargs)
           ^^^^^^^^^^^^^^^^^^^^^^^^^^
  File "/home/nicolaspc/anaconda3/envs/mlops_env/lib/python3.12/site-packages/airflow/models/baseoperator.py", line 406, in wrapper
    return func(self, *args, **kwargs)
           ^^^^^^^^^^^^^^^^^^^^^^^^^^^
  File "/home/nicolaspc/anaconda3/envs/mlops_env/lib/python3.12/site-packages/airflow/operators/python.py", line 238, in execute
    return_value = self.execute_callable()
                   ^^^^^^^^^^^^^^^^^^^^^^^
  File "/home/nicolaspc/anaconda3/envs/mlops_env/lib/python3.12/site-packages/airflow/operators/python.py", line 256, in execute_callable
    return runner.run(*self.op_args, **self.op_kwargs)
           ^^^^^^^^^^^^^^^^^^^^^^^^^^^^^^^^^^^^^^^^^^^
  File "/home/nicolaspc/anaconda3/envs/mlops_env/lib/python3.12/site-packages/airflow/utils/operator_helpers.py", line 252, in run
    return self.func(*args, **kwargs)
           ^^^^^^^^^^^^^^^^^^^^^^^^^^
  File "/home/nicolaspc/airflow/dags/.ipynb_checkpoints/homework_stepik-checkpoint.py", line 64, in init
    experiment_id = mlflow.create_experiment(exp_name, artifact_location=f"s3://test-bucket-nicolas-1/mlflow/{exp_name}")
                    ^^^^^^
NameError: name 'mlflow' is not defined
[2024-08-21T18:40:00.778+0500] {taskinstance.py:1225} INFO - Marking task as FAILED. dag_id=3_models_dag_home, task_id=init, run_id=scheduled__2024-08-20T01:00:00+00:00, execution_date=20240820T010000, start_date=20240821T134000, end_date=20240821T134000
[2024-08-21T18:40:00.789+0500] {taskinstance.py:340} INFO - ::group::Post task execution logs
[2024-08-21T18:40:00.790+0500] {standard_task_runner.py:124} ERROR - Failed to execute job 108 for task init (name 'mlflow' is not defined; 246533)
Traceback (most recent call last):
  File "/home/nicolaspc/anaconda3/envs/mlops_env/lib/python3.12/site-packages/airflow/task/task_runner/standard_task_runner.py", line 117, in _start_by_fork
    ret = args.func(args, dag=self.dag)
          ^^^^^^^^^^^^^^^^^^^^^^^^^^^^^
  File "/home/nicolaspc/anaconda3/envs/mlops_env/lib/python3.12/site-packages/airflow/cli/cli_config.py", line 49, in command
    return func(*args, **kwargs)
           ^^^^^^^^^^^^^^^^^^^^^
  File "/home/nicolaspc/anaconda3/envs/mlops_env/lib/python3.12/site-packages/airflow/utils/cli.py", line 115, in wrapper
    return f(*args, **kwargs)
           ^^^^^^^^^^^^^^^^^^
  File "/home/nicolaspc/anaconda3/envs/mlops_env/lib/python3.12/site-packages/airflow/cli/commands/task_command.py", line 483, in task_run
    task_return_code = _run_task_by_selected_method(args, _dag, ti)
                       ^^^^^^^^^^^^^^^^^^^^^^^^^^^^^^^^^^^^^^^^^^^^
  File "/home/nicolaspc/anaconda3/envs/mlops_env/lib/python3.12/site-packages/airflow/cli/commands/task_command.py", line 256, in _run_task_by_selected_method
    return _run_raw_task(args, ti)
           ^^^^^^^^^^^^^^^^^^^^^^^
  File "/home/nicolaspc/anaconda3/envs/mlops_env/lib/python3.12/site-packages/airflow/cli/commands/task_command.py", line 341, in _run_raw_task
    return ti._run_raw_task(
           ^^^^^^^^^^^^^^^^^
  File "/home/nicolaspc/anaconda3/envs/mlops_env/lib/python3.12/site-packages/airflow/utils/session.py", line 97, in wrapper
    return func(*args, session=session, **kwargs)
           ^^^^^^^^^^^^^^^^^^^^^^^^^^^^^^^^^^^^^^
  File "/home/nicolaspc/anaconda3/envs/mlops_env/lib/python3.12/site-packages/airflow/models/taskinstance.py", line 2995, in _run_raw_task
    return _run_raw_task(
           ^^^^^^^^^^^^^^
  File "/home/nicolaspc/anaconda3/envs/mlops_env/lib/python3.12/site-packages/airflow/models/taskinstance.py", line 273, in _run_raw_task
    TaskInstance._execute_task_with_callbacks(
  File "/home/nicolaspc/anaconda3/envs/mlops_env/lib/python3.12/site-packages/airflow/models/taskinstance.py", line 3149, in _execute_task_with_callbacks
    result = self._execute_task(context, task_orig)
             ^^^^^^^^^^^^^^^^^^^^^^^^^^^^^^^^^^^^^^
  File "/home/nicolaspc/anaconda3/envs/mlops_env/lib/python3.12/site-packages/airflow/models/taskinstance.py", line 3173, in _execute_task
    return _execute_task(self, context, task_orig)
           ^^^^^^^^^^^^^^^^^^^^^^^^^^^^^^^^^^^^^^^
  File "/home/nicolaspc/anaconda3/envs/mlops_env/lib/python3.12/site-packages/airflow/models/taskinstance.py", line 767, in _execute_task
    result = _execute_callable(context=context, **execute_callable_kwargs)
             ^^^^^^^^^^^^^^^^^^^^^^^^^^^^^^^^^^^^^^^^^^^^^^^^^^^^^^^^^^^^^
  File "/home/nicolaspc/anaconda3/envs/mlops_env/lib/python3.12/site-packages/airflow/models/taskinstance.py", line 733, in _execute_callable
    return ExecutionCallableRunner(
           ^^^^^^^^^^^^^^^^^^^^^^^^
  File "/home/nicolaspc/anaconda3/envs/mlops_env/lib/python3.12/site-packages/airflow/utils/operator_helpers.py", line 252, in run
    return self.func(*args, **kwargs)
           ^^^^^^^^^^^^^^^^^^^^^^^^^^
  File "/home/nicolaspc/anaconda3/envs/mlops_env/lib/python3.12/site-packages/airflow/models/baseoperator.py", line 406, in wrapper
    return func(self, *args, **kwargs)
           ^^^^^^^^^^^^^^^^^^^^^^^^^^^
  File "/home/nicolaspc/anaconda3/envs/mlops_env/lib/python3.12/site-packages/airflow/operators/python.py", line 238, in execute
    return_value = self.execute_callable()
                   ^^^^^^^^^^^^^^^^^^^^^^^
  File "/home/nicolaspc/anaconda3/envs/mlops_env/lib/python3.12/site-packages/airflow/operators/python.py", line 256, in execute_callable
    return runner.run(*self.op_args, **self.op_kwargs)
           ^^^^^^^^^^^^^^^^^^^^^^^^^^^^^^^^^^^^^^^^^^^
  File "/home/nicolaspc/anaconda3/envs/mlops_env/lib/python3.12/site-packages/airflow/utils/operator_helpers.py", line 252, in run
    return self.func(*args, **kwargs)
           ^^^^^^^^^^^^^^^^^^^^^^^^^^
  File "/home/nicolaspc/airflow/dags/.ipynb_checkpoints/homework_stepik-checkpoint.py", line 64, in init
    experiment_id = mlflow.create_experiment(exp_name, artifact_location=f"s3://test-bucket-nicolas-1/mlflow/{exp_name}")
                    ^^^^^^
NameError: name 'mlflow' is not defined
[2024-08-21T18:40:00.829+0500] {local_task_job_runner.py:261} INFO - Task exited with return code 1
[2024-08-21T18:40:00.855+0500] {taskinstance.py:3891} INFO - 0 downstream tasks scheduled from follow-on schedule check
[2024-08-21T18:40:00.860+0500] {local_task_job_runner.py:240} INFO - ::endgroup::
